Workbook

Sheet Титул
B3: ПРАКТИЧЕСКАЯ РАБОТА № 9
B4: Определение показателей долговечности системы
B5: Дисциплина: ИТПСИС
B7: Цель работы | C7: Освоить расчёт показателей надёжности для нормального, экспоненциального законов и закона Вейбулла и уметь давать характеристику полученным показателям.
B8: Выполнил(а)
B9: Группа
B10: Дата
B11: Преподаватель
B13: Содержание книги
B14: Нормальный закон | C14: задачи 4.1–4.7, 4.9, 4.10, 4.15
B15: Экспоненциальный закон | C15: задачи 4.8, 4.12, 4.13
B16: Закон Вейбулла | C16: задачи 4.11, 4.14
B17: Графики | C17: P(t), Q(t), λ(t) по расчётным данным
B18: Сводка ответов | C18: все результаты на одном листе
B19: Контрольные вопросы | C19: ответы на вопросы 1–11
B21: Условные обозначения
B22: Синий шрифт на голубом | C22: исходные данные из условия (можно менять — расчёт обновится)
B23: Жирный на оранжевом | C23: итоговый ответ
B24: Жёлтые ячейки на этом листе | C24: заполнить: ФИО, группа, дата, преподаватель

Sheet Нормальный закон
A1: Задача 4.1. Наработки, отвечающие заданной вероятности отказа
A2: Условие | B2: Mt = 2000 ч, σt = 400 ч, закон нормальный. Найти наработки t, при которых вероятность отказа Q равна 0,9; 0,5 и 0,005.
A3: Дано | B3: Средняя наработка до отказа Mt | C3: 2000 | D3: ч | E3: задано
B4: Среднее квадратическое отклонение σt | C4: 400 | D4: ч | E4: задано
A5: Решение | B5: Для нормального закона Q = Φ(Uр), откуда Uр = Φ⁻¹(Q), а искомая наработка t = Mt + Uр·σt. Правый столбец — независимая проверка встроенной функцией НОРМОБР.
B6: Заданная Q | C6: Квантиль Uр = Φ⁻¹(Q) | D6: t = Mt + Uр·σt, ч | E6: Проверка: НОРМОБР(Q; Mt; σt), ч
B7: 0.9 | C7: =NORMSINV(B7) | D7: =$C$3+C7*$C$4 | E7: =NORMINV(B7,$C$3,$C$4)
B8: 0.5 | C8: =NORMSINV(B8) | D8: =$C$3+C8*$C$4 | E8: =NORMINV(B8,$C$3,$C$4)
B9: 0.005 | C9: =NORMSINV(B9) | D9: =$C$3+C9*$C$4 | E9: =NORMINV(B9,$C$3,$C$4)
A10: Ответ | B10: Ответ: t при Q = 0,9 | C10: =D7 | D10: ч
B11: Ответ: t при Q = 0,5 | C11: =D8 | D11: ч | E11: совпадает с Mt, так как Uр = 0
B12: Ответ: t при Q = 0,005 | C12: =D9 | D12: ч
A14: Задача 4.2. Средний ресурс по предельно допустимому значению
A15: Условие | B15: Предельно допустимое значение ресурса 7000 ч, σt = 1000 ч. Найти средний ресурс, вероятность отказа и вероятность безотказной работы при t = 5000 ч.
A16: Дано | B16: Предельно допустимый ресурс tпред | C16: 7000 | D16: ч | E16: задано
B17: Среднее квадратическое отклонение σt | C17: 1000 | D17: ч | E17: задано
B18: Число сигм k | C18: 3 | E18: правило «трёх сигм»: практически весь разброс лежит в пределах Mt ± 3σ
B19: Рассматриваемая наработка t | C19: 5000 | D19: ч | E19: задано
A20: Решение | B20: Средний ресурс Mt = tпред − k·σt | C20: =$C$16-$C$18*$C$17 | D20: ч | E20: предельное значение — верхняя граница Mt + 3σ
B21: Квантиль Uр = (t − Mt)/σt | C21: =($C$19-$C$20)/$C$17
B22: Вероятность отказа Q(t) = Φ(Uр) | C22: =NORMDIST($C$19,$C$20,$C$17,TRUE) | E22: функция НОРМРАСП с интегральным признаком
B23: Вероятность безотказной работы P(t) = 1 − Q(t) | C23: =1-$C$22
A24: Ответ | B24: Ответ: средний ресурс Mt | C24: =$C$20 | D24: ч
B25: Ответ: вероятность отказа Q(5000 ч) | C25: =$C$22
B26: Ответ: вероятность безотказной работы P(5000 ч) | C26: =$C$23
A28: Задача 4.3. Вероятность превышения износом среднего значения не более чем на 5 %
A29: Условие | B29: Средняя величина износа клыка роторного экскаватора 5 мм, дисперсия 0,01 мм². Найти вероятность того, что износ превышает среднее значение не более чем на 5 %.
A30: Дано | B30: Средний износ M | C30: 5 | D30: мм | E30: задано
B31: Дисперсия D | C31: 0.01 | D31: мм² | E31: задано
B32: Допустимое превышение δ | C32: 0.05 | E32: 5 % от среднего
A33: Решение | B33: СКО σ = √D | C33: =SQRT($C$31) | D33: мм
B34: Верхняя граница x = M·(1 + δ) | C34: =$C$30*(1+$C$32) | D34: мм | E34: нужна вероятность P(M < X ≤ x)
B35: Квантиль U = (x − M)/σ | C35: =($C$34-$C$30)/$C$33
B36: P(M < X ≤ x) = Φ(U) − Φ(0) | C36: =NORMDIST($C$35,0,1,TRUE)-NORMDIST(0,0,1,TRUE) | E36: Φ(0) = 0,5
A37: Ответ | B37: Ответ: вероятность P(M < X ≤ 1,05·M) | C37: =$C$36 | E37: ≈ 49 %
A39: Задача 4.4. Показатели надёжности по средней наработке и коэффициенту вариации
A40: Условие | B40: Средняя наработка на отказ 1500 ч, коэффициент вариации 0,3. Определить показатели надёжности для наработок 1000, 2000 и 3000 ч.
A41: Дано | B41: Средняя наработка на отказ Mt | C41: 1500 | D41: ч | E41: задано
B42: Коэффициент вариации v | C42: 0.3 | E42: задано
A43: Решение | B43: СКО σt = v·Mt | C43: =$C$42*$C$41 | D43: ч | E43: из определения v = σt/Mt
...

Sheet Экспоненциальный закон
A1: Задача 4.8. Число отказавших изделий при t = 9000 ч (экспонента со сдвигом)
A2: Условие | B2: Минимальная наработка на отказ 3000 ч, средняя наработка 1200 ч. Найти число отказавших изделий при t = 9000 ч и характеристики надёжности. До t₀ отказов нет, дальше интенсивность постоянна.
A3: Дано | B3: Минимальная наработка t₀ | C3: 3000 | D3: ч | E3: задано
B4: Средняя наработка сверх t₀, 1/λ | C4: 1200 | D4: ч | E4: трактуем как среднее превышение над t₀ (иначе среднее < t₀ — абсурд)
B5: Наработка t | C5: 9000 | D5: ч | E5: задано
B6: Число испытуемых изделий N | C6: 100 | D6: шт | E6: ДОПУЩЕНИЕ: в условии не задано, принято 100 шт (можно изменить)
A7: Решение | B7: Интенсивность отказов λ = 1/m | C7: =1/$C$4 | D7: 1/ч
B8: Время после порога τ = t − t₀ | C8: =$C$5-$C$3 | D8: ч
B9: P(t) = exp(−λ·τ) | C9: =EXP(-$C$7*$C$8)
B10: Q(t) = 1 − P(t) | C10: =1-$C$9
B11: f(t) = λ·P(t) | C11: =$C$7*$C$9 | D11: 1/ч
B12: λ(t) = f(t)/P(t) | C12: =$C$11/$C$9 | D12: 1/ч | E12: при t > t₀ интенсивность постоянна
B13: Полная средняя наработка Mt = t₀ + 1/λ | C13: =$C$3+$C$4 | D13: ч
A14: Ответ | B14: Ответ: число отказавших изделий при t = 9000 ч | C14: =ROUND($C$6*$C$10,0) | D14: шт | E14: для N = 100
B15: Ответ: P(9000 ч) | C15: =$C$9
B16: Ответ: Q(9000 ч) | C16: =$C$10
B17: Ответ: λ(t) | C17: =$C$12 | D17: 1/ч
A19: Задача 4.12. Интенсивность отказов и средняя наработка по вероятности безотказной работы
A20: Условие | B20: Вероятность безотказной работы автоматической линии за 120 ч равна 0,95. Найти интенсивность отказов в момент 120 ч и среднее время безотказной работы (закон экспоненциальный).
A21: Дано | B21: Вероятность безотказной работы P(120) | C21: 0.95 | E21: задано
B22: Время t | C22: 120 | D22: ч | E22: задано
A23: Решение | B23: λ = −ln P(t) / t | C23: =-LN($C$21)/$C$22 | D23: 1/ч | E23: из P = exp(−λt)
B24: Mt = 1/λ | C24: =1/$C$23 | D24: ч
B25: Q(120) = 1 − P | C25: =1-$C$21
B26: f(120) = λ·P | C26: =$C$23*$C$21 | D26: 1/ч
A27: Ответ | B27: Ответ: интенсивность отказов λ(120 ч) | C27: =$C$23 | D27: 1/ч | E27: постоянна на всём периоде
B28: Ответ: среднее время безотказной работы Mt | C28: =$C$24 | D28: ч
A30: Задача 4.13. Показатели по средней наработке
A31: Условие | B31: Среднее время безотказной работы автоматической системы управления 640 ч (закон экспоненциальный). Найти вероятность безотказной работы за 120 ч, частоту и интенсивность отказов в момент 120 ч.
A32: Дано | B32: Среднее время безотказной работы Mt | C32: 640 | D32: ч | E32: задано
B33: Время t | C33: 120 | D33: ч | E33: задано
A34: Решение | B34: λ = 1/Mt | C34: =1/$C$32 | D34: 1/ч
B35: P(120) = exp(−λ·t) | C35: =EXP(-$C$34*$C$33)
B36: f(120) = λ·P(120) | C36: =$C$34*$C$35 | D36: 1/ч | E36: частота (плотность) отказов
A37: Ответ | B37: Ответ: P(120 ч) | C37: =$C$35
B38: Ответ: частота отказов f(120 ч) | C38: =$C$36 | D38: 1/ч
B39: Ответ: интенсивность отказов λ | C39: =$C$34 | D39: 1/ч

Sheet Закон Вейбулла
A1: Задача 4.11. Закон Вейбулла, t = 100 ч
A2: Условие | B2: Наработка до отказа подчиняется закону Вейбулла с α = 1,5 и λ = 10⁻⁴ 1/ч. Найти количественные характеристики надёжности за время работы 100 ч.
A3: Дано | B3: Параметр формы α | C3: 1.5 | E3: задано
B4: Параметр масштаба λ | C4: 0.0001 | D4: 1/ч^α | E4: задано
B5: Время работы t | C5: 100 | D5: ч | E5: задано
A6: Решение | B6: Показатель экспоненты λ·t^α | C6: =$C$4*$C$5^$C$3
B7: P(t) = exp(−λ·t^α) | C7: =EXP(-$C$6)
B8: Q(t) = 1 − P(t) | C8: =1-$C$7
B9: λ(t) = λ·α·t^(α−1) | C9: =$C$4*$C$3*$C$5^($C$3-1) | D9: 1/ч | E9: при α > 1 возрастает
B10: f(t) = λ(t)·P(t) | C10: =$C$9*$C$7 | D10: 1/ч
B11: Γ(1 + 1/α) | C11: =EXP(GAMMALN(1+1/$C$3)) | E11: Γ(x) = EXP(ГАММАНЛОГ(x))
B12: Γ(1 + 2/α) | C12: =EXP(GAMMALN(1+2/$C$3))
B13: Средняя наработка Mt = Γ(1+1/α) / λ^(1/α) | C13: =$C$11/$C$4^(1/$C$3) | D13: ч
B14: СКО σt = √[(Γ(1+2/α) − Γ²(1+1/α)) / λ^(2/α)] | C14: =SQRT(($C$12-$C$11^2)/$C$4^(2/$C$3)) | D14: ч
B15: Коэффициент вариации v = σt/Mt | C15: =$C$14/$C$13
A16: Ответ | B16: Ответ: P(100 ч) | C16: =$C$7
B17: Ответ: Q(100 ч) | C17: =$C$8
B18: Ответ: f(100 ч) | C18: =$C$10 | D18: 1/ч
B19: Ответ: λ(100 ч) | C19: =$C$9 | D19: 1/ч
B20: Ответ: средняя наработка Mt | C20: =$C$13 | D20: ч
B21: Ответ: СКО σt | C21: =$C$14 | D21: ч
B22: Ответ: коэффициент вариации v | C22: =$C$15
A24: Задача 4.14. Закон Вейбулла, t = 150 ч
A25: Условие | B25: Время исправной работы скоростных шарикоподшипников подчиняется закону Вейбулла с α = 2,6 и λ = 1,65·10⁻⁷ 1/ч. Найти характеристики надёжности для времени 150 ч и среднее время безотказной работы.
A26: Дано | B26: Параметр формы α | C26: 2.6 | E26: задано
B27: Параметр масштаба λ | C27: 1.65e-07 | D27: 1/ч^α | E27: задано
B28: Время работы t | C28: 150 | D28: ч | E28: задано
A29: Решение | B29: Показатель экспоненты λ·t^α | C29: =$C$27*$C$28^$C$26
B30: P(t) = exp(−λ·t^α) | C30: =EXP(-$C$29)
B31: Q(t) = 1 − P(t) | C31: =1-$C$30
B32: λ(t) = λ·α·t^(α−1) | C32: =$C$27*$C$26*$C$28^($C$26-1) | D32: 1/ч | E32: при α > 1 возрастает
B33: f(t) = λ(t)·P(t) | C33: =$C$32*$C$30 | D33: 1/ч
B34: Γ(1 + 1/α) | C34: =EXP(GAMMALN(1+1/$C$26)) | E34: Γ(x) = EXP(ГАММАНЛОГ(x))
B35: Γ(1 + 2/α) | C35: =EXP(GAMMALN(1+2/$C$26))
B36: Средняя наработка Mt = Γ(1+1/α) / λ^(1/α) | C36: =$C$34/$C$27^(1/$C$26) | D36: ч
B37: СКО σt = √[(Γ(1+2/α) − Γ²(1+1/α)) / λ^(2/α)] | C37: =SQRT(($C$35-$C$34^2)/$C$27^(2/$C$26)) | D37: ч
B38: Коэффициент вариации v = σt/Mt | C38: =$C$37/$C$36
A39: Ответ | B39: Ответ: P(150 ч) | C39: =$C$30
B40: Ответ: Q(150 ч) | C40: =$C$31
B41: Ответ: f(150 ч) | C41: =$C$33 | D41: 1/ч
...

Sheet Графики
A1: Графики показателей надёжности (данные считаются по параметрам задач 4.4, 4.11 и 4.13)
A3: t, ч (4.4) | B3: P(t), нормальный | C3: Q(t), нормальный | E3: t, ч (4.11/4.13) | F3: P(t) Вейбулла α=1,5 | G3: P(t) экспонента | H3: λ(t) Вейбулла | I3: λ(t) экспонента
A4: 0 | B4: =1-NORMDIST(A4,'Нормальный закон'!$C$41,'Нормальный закон'!$C$43,TRUE) | C4: =NORMDIST(A4,'Нормальный закон'!$C$41,'Нормальный закон'!$C$43,TRUE) | E4: 0 | F4: =EXP(-'Закон Вейбулла'!$C$4*E4^'Закон Вейбулла'!$C$3) | G4: =EXP(-'Экспоненциальный закон'!$C$34*E4) | H4: ='Закон Вейбулла'!$C$4*'Закон Вейбулла'!$C$3*E4^('Закон Вейбулла'!$C$3-1) | I4: ='Экспоненциальный закон'!$C$34
A5: 150 | B5: =1-NORMDIST(A5,'Нормальный закон'!$C$41,'Нормальный закон'!$C$43,TRUE) | C5: =NORMDIST(A5,'Нормальный закон'!$C$41,'Нормальный закон'!$C$43,TRUE) | E5: 50 | F5: =EXP(-'Закон Вейбулла'!$C$4*E5^'Закон Вейбулла'!$C$3) | G5: =EXP(-'Экспоненциальный закон'!$C$34*E5) | H5: ='Закон Вейбулла'!$C$4*'Закон Вейбулла'!$C$3*E5^('Закон Вейбулла'!$C$3-1) | I5: ='Экспоненциальный закон'!$C$34
A6: 300 | B6: =1-NORMDIST(A6,'Нормальный закон'!$C$41,'Нормальный закон'!$C$43,TRUE) | C6: =NORMDIST(A6,'Нормальный закон'!$C$41,'Нормальный закон'!$C$43,TRUE) | E6: 100 | F6: =EXP(-'Закон Вейбулла'!$C$4*E6^'Закон Вейбулла'!$C$3) | G6: =EXP(-'Экспоненциальный закон'!$C$34*E6) | H6: ='Закон Вейбулла'!$C$4*'Закон Вейбулла'!$C$3*E6^('Закон Вейбулла'!$C$3-1) | I6: ='Экспоненциальный закон'!$C$34
A7: 450 | B7: =1-NORMDIST(A7,'Нормальный закон'!$C$41,'Нормальный закон'!$C$43,TRUE) | C7: =NORMDIST(A7,'Нормальный закон'!$C$41,'Нормальный закон'!$C$43,TRUE) | E7: 150 | F7: =EXP(-'Закон Вейбулла'!$C$4*E7^'Закон Вейбулла'!$C$3) | G7: =EXP(-'Экспоненциальный закон'!$C$34*E7) | H7: ='Закон Вейбулла'!$C$4*'Закон Вейбулла'!$C$3*E7^('Закон Вейбулла'!$C$3-1) | I7: ='Экспоненциальный закон'!$C$34
A8: 600 | B8: =1-NORMDIST(A8,'Нормальный закон'!$C$41,'Нормальный закон'!$C$43,TRUE) | C8: =NORMDIST(A8,'Нормальный закон'!$C$41,'Нормальный закон'!$C$43,TRUE) | E8: 200 | F8: =EXP(-'Закон Вейбулла'!$C$4*E8^'Закон Вейбулла'!$C$3) | G8: =EXP(-'Экспоненциальный закон'!$C$34*E8) | H8: ='Закон Вейбулла'!$C$4*'Закон Вейбулла'!$C$3*E8^('Закон Вейбулла'!$C$3-1) | I8: ='Экспоненциальный закон'!$C$34
A9: 750 | B9: =1-NORMDIST(A9,'Нормальный закон'!$C$41,'Нормальный закон'!$C$43,TRUE) | C9: =NORMDIST(A9,'Нормальный закон'!$C$41,'Нормальный закон'!$C$43,TRUE) | E9: 250 | F9: =EXP(-'Закон Вейбулла'!$C$4*E9^'Закон Вейбулла'!$C$3) | G9: =EXP(-'Экспоненциальный закон'!$C$34*E9) | H9: ='Закон Вейбулла'!$C$4*'Закон Вейбулла'!$C$3*E9^('Закон Вейбулла'!$C$3-1) | I9: ='Экспоненциальный закон'!$C$34
A10: 900 | B10: =1-NORMDIST(A10,'Нормальный закон'!$C$41,'Нормальный закон'!$C$43,TRUE) | C10: =NORMDIST(A10,'Нормальный закон'!$C$41,'Нормальный закон'!$C$43,TRUE) | E10: 300 | F10: =EXP(-'Закон Вейбулла'!$C$4*E10^'Закон Вейбулла'!$C$3) | G10: =EXP(-'Экспоненциальный закон'!$C$34*E10) | H10: ='Закон Вейбулла'!$C$4*'Закон Вейбулла'!$C$3*E10^('Закон Вейбулла'!$C$3-1) | I10: ='Экспоненциальный закон'!$C$34
A11: 1050 | B11: =1-NORMDIST(A11,'Нормальный закон'!$C$41,'Нормальный закон'!$C$43,TRUE) | C11: =NORMDIST(A11,'Нормальный закон'!$C$41,'Нормальный закон'!$C$43,TRUE) | E11: 350 | F11: =EXP(-'Закон Вейбулла'!$C$4*E11^'Закон Вейбулла'!$C$3) | G11: =EXP(-'Экспоненциальный закон'!$C$34*E11) | H11: ='Закон Вейбулла'!$C$4*'Закон Вейбулла'!$C$3*E11^('Закон Вейбулла'!$C$3-1) | I11: ='Экспоненциальный закон'!$C$34
A12: 1200 | B12: =1-NORMDIST(A12,'Нормальный закон'!$C$41,'Нормальный закон'!$C$43,TRUE) | C12: =NORMDIST(A12,'Нормальный закон'!$C$41,'Нормальный закон'!$C$43,TRUE) | E12: 400 | F12: =EXP(-'Закон Вейбулла'!$C$4*E12^'Закон Вейбулла'!$C$3) | G12: =EXP(-'Экспоненциальный закон'!$C$34*E12) | H12: ='Закон Вейбулла'!$C$4*'Закон Вейбулла'!$C$3*E12^('Закон Вейбулла'!$C$3-1) | I12: ='Экспоненциальный закон'!$C$34
A13: 1350 | B13: =1-NORMDIST(A13,'Нормальный закон'!$C$41,'Нормальный закон'!$C$43,TRUE) | C13: =NORMDIST(A13,'Нормальный закон'!$C$41,'Нормальный закон'!$C$43,TRUE) | E13: 450 | F13: =EXP(-'Закон Вейбулла'!$C$4*E13^'Закон Вейбулла'!$C$3) | G13: =EXP(-'Экспоненциальный закон'!$C$34*E13) | H13: ='Закон Вейбулла'!$C$4*'Закон Вейбулла'!$C$3*E13^('Закон Вейбулла'!$C$3-1) | I13: ='Экспоненциальный закон'!$C$34
A14: 1500 | B14: =1-NORMDIST(A14,'Нормальный закон'!$C$41,'Нормальный закон'!$C$43,TRUE) | C14: =NORMDIST(A14,'Нормальный закон'!$C$41,'Нормальный закон'!$C$43,TRUE) | E14: 500 | F14: =EXP(-'Закон Вейбулла'!$C$4*E14^'Закон Вейбулла'!$C$3) | G14: =EXP(-'Экспоненциальный закон'!$C$34*E14) | H14: ='Закон Вейбулла'!$C$4*'Закон Вейбулла'!$C$3*E14^('Закон Вейбулла'!$C$3-1) | I14: ='Экспоненциальный закон'!$C$34
A15: 1650 | B15: =1-NORMDIST(A15,'Нормальный закон'!$C$41,'Нормальный закон'!$C$43,TRUE) | C15: =NORMDIST(A15,'Нормальный закон'!$C$41,'Нормальный закон'!$C$43,TRUE) | E15: 550 | F15: =EXP(-'Закон Вейбулла'!$C$4*E15^'Закон Вейбулла'!$C$3) | G15: =EXP(-'Экспоненциальный закон'!$C$34*E15) | H15: ='Закон Вейбулла'!$C$4*'Закон Вейбулла'!$C$3*E15^('Закон Вейбулла'!$C$3-1) | I15: ='Экспоненциальный закон'!$C$34
... A24: 3000 | B24: =1-NORMDIST(A24,'Нормальный закон'!$C$41,'Нормальный закон'!$C$43,TRUE) | C24: =NORMDIST(A24,'Нормальный закон'!$C$41,'Нормальный закон'!$C$43,TRUE) | E24: 1000 | F24: =EXP(-'Закон Вейбулла'!$C$4*E24^'Закон Вейбулла'!$C$3) | G24: =EXP(-'Экспоненциальный закон'!$C$34*E24) | H24: ='Закон Вейбулла'!$C$4*'Закон Вейбулла'!$C$3*E24^('Закон Вейбулла'!$C$3-1) | I24: ='Экспоненциальный закон'!$C$34

Sheet Сводка ответов
A1: Сводка ответов по задачам 4.1–4.15
A3: Задача | B3: Закон | C3: Искомая величина | D3: Результат | E3: Ед.
A4: 4.1 | B4: Нормальный | C4: t при Q = 0,9 | D4: ='Нормальный закон'!C10 | E4: ч
A5: 4.1 | B5: Нормальный | C5: t при Q = 0,5 | D5: ='Нормальный закон'!C11 | E5: ч
A6: 4.1 | B6: Нормальный | C6: t при Q = 0,005 | D6: ='Нормальный закон'!C12 | E6: ч
A7: 4.2 | B7: Нормальный | C7: средний ресурс Mt | D7: ='Нормальный закон'!C24 | E7: ч
A8: 4.2 | B8: Нормальный | C8: вероятность отказа Q(5000 ч) | D8: ='Нормальный закон'!C25
A9: 4.2 | B9: Нормальный | C9: вероятность безотказной работы P(5000 ч) | D9: ='Нормальный закон'!C26
A10: 4.3 | B10: Нормальный | C10: вероятность P(M < X ≤ 1,05·M) | D10: ='Нормальный закон'!C37
A11: 4.4 | B11: Нормальный | C11: P(1000 ч) | D11: ='Нормальный закон'!E45
A12: 4.4 | B12: Нормальный | C12: Q(1000 ч) | D12: ='Нормальный закон'!D45
A13: 4.4 | B13: Нормальный | C13: λ(1000 ч) | D13: ='Нормальный закон'!G45 | E13: 1/ч
A14: 4.4 | B14: Нормальный | C14: P(2000 ч) | D14: ='Нормальный закон'!E46
A15: 4.4 | B15: Нормальный | C15: Q(2000 ч) | D15: ='Нормальный закон'!D46
A16: 4.4 | B16: Нормальный | C16: λ(2000 ч) | D16: ='Нормальный закон'!G46 | E16: 1/ч
A17: 4.4 | B17: Нормальный | C17: P(3000 ч) | D17: ='Нормальный закон'!E47
A18: 4.4 | B18: Нормальный | C18: Q(3000 ч) | D18: ='Нормальный закон'!D47
A19: 4.4 | B19: Нормальный | C19: λ(3000 ч) | D19: ='Нормальный закон'!G47 | E19: 1/ч
A20: 4.5 | B20: Нормальный | C20: P(1000 ч) | D20: ='Нормальный закон'!E59
A21: 4.5 | B21: Нормальный | C21: Q(1000 ч) | D21: ='Нормальный закон'!D59
A22: 4.5 | B22: Нормальный | C22: λ(1000 ч) | D22: ='Нормальный закон'!G59 | E22: 1/ч
A23: 4.5 | B23: Нормальный | C23: P(2000 ч) | D23: ='Нормальный закон'!E60
A24: 4.5 | B24: Нормальный | C24: Q(2000 ч) | D24: ='Нормальный закон'!D60
A25: 4.5 | B25: Нормальный | C25: λ(2000 ч) | D25: ='Нормальный закон'!G60 | E25: 1/ч
A26: 4.5 | B26: Нормальный | C26: P(3000 ч) | D26: ='Нормальный закон'!E61
A27: 4.5 | B27: Нормальный | C27: Q(3000 ч) | D27: ='Нормальный закон'!D61
A28: 4.5 | B28: Нормальный | C28: λ(3000 ч) | D28: ='Нормальный закон'!G61 | E28: 1/ч
A29: 4.5 | B29: Нормальный | C29: средний ресурс Mt | D29: ='Нормальный закон'!C62 | E29: ч
A30: 4.6 | B30: Нормальный | C30: отказавших задвижек в интервале 1500–3000 ч | D30: ='Нормальный закон'!C82 | E30: шт
A31: 4.7 | B31: Нормальный | C31: отказавших долот в интервале 200–250 ч | D31: ='Нормальный закон'!C102 | E31: шт
A32: 4.8 | B32: Экспоненциальный | C32: число отказавших изделий при t = 9000 ч | D32: ='Экспоненциальный закон'!C14 | E32: шт
A33: 4.8 | B33: Экспоненциальный | C33: P(9000 ч) | D33: ='Экспоненциальный закон'!C15
A34: 4.8 | B34: Экспоненциальный | C34: Q(9000 ч) | D34: ='Экспоненциальный закон'!C16
A35: 4.8 | B35: Экспоненциальный | C35: λ(t) | D35: ='Экспоненциальный закон'!C17 | E35: 1/ч
A36: 4.9 | B36: Нормальный | C36: вероятность отказа Q(1500 ч) | D36: ='Нормальный закон'!C113
A37: 4.10 | B37: Нормальный | C37: вероятность отказа Q(1200 ч) | D37: ='Нормальный закон'!C125
A38: 4.10 | B38: Нормальный | C38: Mt (характеристика распределения) | D38: ='Нормальный закон'!C126 | E38: ч
A39: 4.10 | B39: Нормальный | C39: σt (характеристика распределения) | D39: ='Нормальный закон'!C127 | E39: ч
A40: 4.11 | B40: Вейбулла | C40: P(100 ч) | D40: ='Закон Вейбулла'!C16
A41: 4.11 | B41: Вейбулла | C41: Q(100 ч) | D41: ='Закон Вейбулла'!C17
...

Sheet Контрольные вопросы
A1: Ответы на контрольные вопросы
A3: № | B3: Вопрос | C3: Ответ
A4: 1 | B4: Что представляет собой закон распределения случайной величины? | C4: Закон распределения — это правило, которое каждому возможному значению случайной величины (или интервалу значений) ставит в соответствие вероятность. Для наработки T до отказа его выражают функцией распределения F(t) = P(T < t), совпадающей с вероятностью отказа Q(t), либо плотностью f(t) = dF/dt (частотой отказов). Зная закон, можно найти все остальные показатели: P(t) = 1 − F(t); λ(t) = f(t)/P(t); Mt = ∫P(t)dt от 0 до ∞.
A5: 2 | B5: Для расчёта каких показателей и технических систем применяется нормальный закон распределения? | C5: Нормальный закон (закон Гаусса) уместен, когда отказ наступает как итог суммирования множества малых независимых воздействий, а разброс ресурса симметричен относительно среднего: износ, усталость, старение, коррозия. Обычно он адекватен при коэффициенте вариации v = σt/Mt менее 0,3. Типичные объекты — подшипники, зубчатые и ременные передачи, тормозные колодки, режущий инструмент, а в ИТ — вентиляторы, жёсткие диски, аккумуляторы ИБП. Рассчитывают Mt, σt, P(t), Q(t), f(t), λ(t), а также гарантированный (γ-процентный) ресурс.
A6: 3 | B6: Расчёт показателей надёжности, подчиняющихся нормальному закону распределения. | C6: Исходные параметры — Mt и σt (или v = σt/Mt). Сначала находят квантиль Uр = (t − Mt)/σt. Затем Q(t) = Φ(Uр) и P(t) = 1 − Φ(Uр) = Φ(−Uр), где Φ — функция нормированного нормального распределения (в Excel НОРМСТРАСП / NORMSDIST или НОРМРАСП / NORMDIST). Плотность f(t) = φ(Uр)/σt, интенсивность отказов λ(t) = f(t)/P(t). Обратная задача: по заданной Q находят Uр = НОРМСТОБР(Q) и t = Mt + Uр·σt (задача 4.1). Примеры: 4.1–4.7, 4.9, 4.10, 4.15.
A7: 4 | B7: Для расчёта каких показателей и технических систем применяется экспоненциальный закон распределения? | C7: Экспоненциальный закон описывает внезапные отказы при постоянной интенсивности λ = const, то есть период нормальной эксплуатации — после приработки и до начала старения. Применим к радиоэлектронным и электронным элементам, сложным системам из большого числа разнородных элементов, восстанавливаемым объектам с простейшим потоком отказов. В ИТ: серверы, сетевое оборудование, платы и блоки питания в «середине жизни». Свойство отсутствия последействия: вероятность безотказной работы на интервале не зависит от того, как долго объект уже работал.
A8: 5 | B8: Расчёт показателей надёжности, подчиняющихся экспоненциальному закону распределения. | C8: P(t) = exp(−λt); Q(t) = 1 − exp(−λt); f(t) = λ·exp(−λt); λ(t) = λ = const; Mt = 1/λ; σt = 1/λ, поэтому v = 1. При λt < 0,1 допустимо приближение P(t) ≈ 1 − λt. Если известна вероятность P(t₀), то λ = −ln P(t₀)/t₀ (задача 4.12); если известна средняя наработка, то λ = 1/Mt (задача 4.13). Для «экспоненты со сдвигом» (задача 4.8) время отсчитывают от порога t₀: P(t) = exp(−λ(t − t₀)).
A9: 6 | B9: Для расчёта каких показателей и технических систем применяется закон распределения Вейбулла? | C9: Закон Вейбулла — гибкая двухпараметрическая модель, в которой параметр формы α определяет характер отказов: α < 1 — приработка (λ(t) убывает), α = 1 — нормальная работа (переходит в экспоненциальный закон), α > 1 — износ и старение (λ(t) растёт). Применяется для подшипников, деталей, разрушающихся от усталости, полупроводниковых и электровакуумных приборов, механических узлов, а также при обработке малой выборки отказов.
A10: 7 | B10: Расчёт показателей надёжности, подчиняющихся закону распределения Вейбулла. | C10: Параметры: α (форма) и λ (масштаб). P(t) = exp(−λ·t^α); Q(t) = 1 − P(t); λ(t) = λ·α·t^(α−1); f(t) = λ(t)·P(t). Средняя наработка Mt = Γ(1 + 1/α)/λ^(1/α); дисперсия σt² = [Γ(1 + 2/α) − Γ²(1 + 1/α)]/λ^(2/α). В Excel гамма-функцию получают как EXP(ГАММАНЛОГ(x)). Примеры — задачи 4.11 и 4.14.
A11: 8 | B11: Для расчёта каких показателей и технических систем применяется гамма-распределение? | C11: Гамма-распределение описывает время до k-го события, например наработку до k-го отказа или наработку системы с резервированием замещением (основной элемент и k − 1 резервных с одинаковой λ). При целом k его называют распределением Эрланга, при k = 1 оно вырождается в экспоненциальное. Применяют для резервированных систем, ремонтируемых изделий и при описании времени восстановления.
A12: 9 | B12: Расчёт показателей надёжности, подчиняющихся гамма-распределению. | C12: Параметры: k (форма) и λ (масштаб). Плотность f(t) = λ^k·t^(k−1)·exp(−λt)/Γ(k). Вероятность отказа Q(t) в Excel — ГАММАРАСП(t; k; 1/λ; ИСТИНА) (GAMMADIST), P(t) = 1 − Q(t). Для целого k: P(t) = exp(−λt)·Σ(λt)^i/i!, i = 0…k−1. Mt = k/λ; σt² = k/λ²; v = 1/√k; λ(t) = f(t)/P(t).
A13: 10 | B13: Для расчёта каких показателей и технических систем применяется логарифмически нормальное распределение? | C13: Логарифмически нормальное распределение применяют, когда нормально распределён не сам ресурс, а его логарифм. Это характерно для усталостных разрушений, износа при накоплении повреждений, коррозии, старения изоляции, отказов полупроводниковых приборов, а также для времени ремонта оборудования. Оно подходит для величин с асимметрией и «тяжёлым» правым хвостом.
A14: 11 | B14: Расчёт показателей надёжности, подчиняющихся логарифмически нормальному распределению. | C14: Параметры: μ и σ — среднее и СКО натурального логарифма наработки. Квантиль U = (ln t − μ)/σ; Q(t) = Φ(U), P(t) = 1 − Φ(U); в Excel ЛОГНОРМРАСП(t; μ; σ) (LOGNORMDIST). Плотность f(t) = exp(−(ln t − μ)²/(2σ²))/(σ·t·√(2π)); λ(t) = f(t)/P(t). Mt = exp(μ + σ²/2); σt² = (exp(σ²) − 1)·exp(2μ + σ²).
